util.py[LINE:64]# ERROR    [2017-11-14 22:55:26,769]  IndexError occurred, args=('list index out of range',)
Traceback (most recent call last):
  File "/usr/local/lib/python3.6/site-packages/telebot/util.py", line 58, in run
    task(*args, **kwargs)
  File "<string>", line 166, in artist_search
IndexError: list index out of range

<string>[LINE:163]# ERROR    [2017-11-14 22:56:46,975]  Ooops
<string>[LINE:173]# ERROR    [2017-11-14 22:59:34,372]  Ooops
<string>[LINE:173]# ERROR    [2017-11-14 22:59:43,229]  Ooops
util.py[LINE:64]# ERROR    [2017-11-14 23:00:05,086]  KeyError occurred, args=('data',)
Traceback (most recent call last):
  File "/usr/local/lib/python3.6/site-packages/telebot/util.py", line 58, in run
    task(*args, **kwargs)
  File "<string>", line 120, in event_search_by_genre
  File "/Users/lostmap/Documents/Programming/Python/technopark_bot/musicgraph1.py", line 14, in get_by_genre
    artists = data['data']
KeyError: 'data'

<string>[LINE:108]# ERROR    [2017-11-14 23:00:51,342]  Ooops
<string>[LINE:108]# ERROR    [2017-11-14 23:01:08,527]  Ooops
<string>[LINE:108]# ERROR    [2017-11-14 23:02:01,996]  Ooops
